[2025-10-03T17:54:20.333+0000] {taskinstance.py:1956} INFO - Dependencies all met for dep_context=non-requeueable deps ti=<TaskInstance: sales_revenue_pipeline.create_sales_table scheduled__2025-10-02T00:00:00+00:00 [queued]>
[2025-10-03T17:54:20.348+0000] {taskinstance.py:1956} INFO - Dependencies all met for dep_context=requeueable deps ti=<TaskInstance: sales_revenue_pipeline.create_sales_table scheduled__2025-10-02T00:00:00+00:00 [queued]>
[2025-10-03T17:54:20.349+0000] {taskinstance.py:2170} INFO - Starting attempt 2 of 2
[2025-10-03T17:54:20.375+0000] {taskinstance.py:2191} INFO - Executing <Task(PythonOperator): create_sales_table> on 2025-10-02 00:00:00+00:00
[2025-10-03T17:54:20.387+0000] {standard_task_runner.py:60} INFO - Started process 319 to run task
[2025-10-03T17:54:20.395+0000] {standard_task_runner.py:87} INFO - Running: ['***', 'tasks', 'run', 'sales_revenue_pipeline', 'create_sales_table', 'scheduled__2025-10-02T00:00:00+00:00', '--job-id', '5', '--raw', '--subdir', 'DAGS_FOLDER/sales_revenue_pipeline.py', '--cfg-path', '/tmp/tmp5k5w9ull']
[2025-10-03T17:54:20.400+0000] {standard_task_runner.py:88} INFO - Job 5: Subtask create_sales_table
[2025-10-03T17:54:20.571+0000] {task_command.py:423} INFO - Running <TaskInstance: sales_revenue_pipeline.create_sales_table scheduled__2025-10-02T00:00:00+00:00 [running]> on host 06d653bd8bf1
[2025-10-03T17:54:20.735+0000] {taskinstance.py:2480} INFO - Exporting env vars: AIRFLOW_CTX_DAG_OWNER='***' AIRFLOW_CTX_DAG_ID='sales_revenue_pipeline' AIRFLOW_CTX_TASK_ID='create_sales_table' AIRFLOW_CTX_EXECUTION_DATE='2025-10-02T00:00:00+00:00' AIRFLOW_CTX_TRY_NUMBER='2' AIRFLOW_CTX_DAG_RUN_ID='scheduled__2025-10-02T00:00:00+00:00'
[2025-10-03T17:54:20.809+0000] {taskinstance.py:2698} ERROR - Task failed with exception
Traceback (most recent call last):
  File "/home/airflow/.local/lib/python3.8/site-packages/airflow/models/taskinstance.py", line 433, in _execute_task
    result = execute_callable(context=context, **execute_callable_kwargs)
  File "/home/airflow/.local/lib/python3.8/site-packages/airflow/operators/python.py", line 199, in execute
    return_value = self.execute_callable()
  File "/home/airflow/.local/lib/python3.8/site-packages/airflow/operators/python.py", line 216, in execute_callable
    return self.python_callable(*self.op_args, **self.op_kwargs)
  File "/opt/airflow/dags/sales_revenue_pipeline.py", line 32, in create_sales_table
    hook.run(create_table_sql)
  File "/home/airflow/.local/lib/python3.8/site-packages/airflow/providers/common/sql/hooks/sql.py", line 391, in run
    with closing(self.get_conn()) as conn:
  File "/home/airflow/.local/lib/python3.8/site-packages/airflow/providers/postgres/hooks/postgres.py", line 128, in get_conn
    conn = deepcopy(self.connection or self.get_connection(conn_id))
  File "/home/airflow/.local/lib/python3.8/site-packages/airflow/hooks/base.py", line 82, in get_connection
    conn = Connection.get_connection_from_secrets(conn_id)
  File "/home/airflow/.local/lib/python3.8/site-packages/airflow/models/connection.py", line 479, in get_connection_from_secrets
    raise AirflowNotFoundException(f"The conn_id `{conn_id}` isn't defined")
airflow.exceptions.AirflowNotFoundException: The conn_id `postgres_default` isn't defined
[2025-10-03T17:54:20.835+0000] {taskinstance.py:1138} INFO - Marking task as FAILED. dag_id=sales_revenue_pipeline, task_id=create_sales_table, execution_date=20251002T000000, start_date=20251003T175420, end_date=20251003T175420
[2025-10-03T17:54:20.881+0000] {standard_task_runner.py:107} ERROR - Failed to execute job 5 for task create_sales_table (The conn_id `postgres_default` isn't defined; 319)
[2025-10-03T17:54:20.933+0000] {local_task_job_runner.py:234} INFO - Task exited with return code 1
[2025-10-03T17:54:21.032+0000] {taskinstance.py:3280} INFO - 0 downstream tasks scheduled from follow-on schedule check
